Watching for file changes with StatReloader
Performing system checks...

System check identified no issues (0 silenced).
May 13, 2022 - 11:10:53
Django version 4.1.dev20220512051916, using settings 'mydjangoapp.settings'
Starting development server at http://0.0.0.0:8000/
Quit the server with CONTROL-C.
[13/May/2022 11:11:03] "GET / HTTP/1.1" 200 10681
[13/May/2022 15:10:52] "GET / HTTP/1.1" 200 10681
[13/May/2022 15:10:52] "GET /static/admin/css/fonts.css HTTP/1.1" 304 0
[13/May/2022 15:10:52] "GET /static/admin/fonts/Roboto-Bold-webfont.woff HTTP/1.1" 304 0
[13/May/2022 15:10:52] "GET /static/admin/fonts/Roboto-Light-webfont.woff HTTP/1.1" 304 0
[13/May/2022 15:10:52] "GET /static/admin/fonts/Roboto-Regular-webfont.woff HTTP/1.1" 304 0
[13/May/2022 15:10:53] "GET / HTTP/1.1" 200 10681
/home/ubuntu/github/mydjangoapp/mydjangoapp/settings.py changed, reloading.
Watching for file changes with StatReloader
Performing system checks...

System check identified no issues (0 silenced).
May 16, 2022 - 11:01:31
Django version 4.1.dev20220512051916, using settings 'mydjangoapp.settings'
Starting development server at http://0.0.0.0:8000/
Quit the server with CONTROL-C.
/home/ubuntu/github/mydjangoapp/mydjangoapp/urls.py changed, reloading.
Watching for file changes with StatReloader
Performing system checks...

Exception in thread django-main-thread:
Traceback (most recent call last):
  File "/usr/lib/python3.8/threading.py", line 932, in _bootstrap_inner
    self.run()
  File "/usr/lib/python3.8/threading.py", line 870, in run
    self._target(*self._args, **self._kwargs)
  File "/home/ubuntu/github/django/django/utils/autoreload.py", line 64, in wrapper
    fn(*args, **kwargs)
  File "/home/ubuntu/github/django/django/core/management/commands/runserver.py", line 134, in inner_run
    self.check(display_num_errors=True)
  File "/home/ubuntu/github/django/django/core/management/base.py", line 475, in check
    all_issues = checks.run_checks(
  File "/home/ubuntu/github/django/django/core/checks/registry.py", line 88, in run_checks
    new_errors = check(app_configs=app_configs, databases=databases)
  File "/home/ubuntu/github/django/django/core/checks/urls.py", line 14, in check_url_config
    return check_resolver(resolver)
  File "/home/ubuntu/github/django/django/core/checks/urls.py", line 24, in check_resolver
    return check_method()
  File "/home/ubuntu/github/django/django/urls/resolvers.py", line 494, in check
    for pattern in self.url_patterns:
  File "/home/ubuntu/github/django/django/utils/functional.py", line 57, in __get__
    res = instance.__dict__[self.name] = self.func(instance)
  File "/home/ubuntu/github/django/django/urls/resolvers.py", line 715, in url_patterns
    patterns = getattr(self.urlconf_module, "urlpatterns", self.urlconf_module)
  File "/home/ubuntu/github/django/django/utils/functional.py", line 57, in __get__
    res = instance.__dict__[self.name] = self.func(instance)
  File "/home/ubuntu/github/django/django/urls/resolvers.py", line 708, in urlconf_module
    return import_module(self.urlconf_name)
  File "/usr/lib/python3.8/importlib/__init__.py", line 127, in import_module
    return _bootstrap._gcd_import(name[level:], package, level)
  File "<frozen importlib._bootstrap>", line 1014, in _gcd_import
  File "<frozen importlib._bootstrap>", line 991, in _find_and_load
  File "<frozen importlib._bootstrap>", line 975, in _find_and_load_unlocked
  File "<frozen importlib._bootstrap>", line 671, in _load_unlocked
  File "<frozen importlib._bootstrap_external>", line 783, in exec_module
  File "<frozen importlib._bootstrap>", line 219, in _call_with_frames_removed
  File "/home/ubuntu/github/mydjangoapp/mydjangoapp/urls.py", line 21, in <module>
    path('', views.index),
NameError: name 'views' is not defined
